{
 "cells": [
  {
   "cell_type": "code",
   "execution_count": 21,
   "id": "a9093d21",
   "metadata": {},
   "outputs": [],
   "source": [
    "import re\n",
    "\n",
    "# Read the contents of the TXT file\n",
    "with open('[English] Cybersecurity IDR_ Incident Detection & Response _ Google Cybersecurity Certificate [DownSub.com].txt', 'r') as file:\n",
    "    text = file.read()\n",
    "    \n",
    "# Replace line breaks and paragraphs with spaces\n",
    "text = re.sub(r'[\\n\\r]+', ' ', text)\n",
    "\n",
    "# Save the cleaned text to a new file or use it for further analysis\n",
    "with open('cleaned_text.txt', 'w') as file:\n",
    "    file.write(text)"
   ]
  },
  {
   "cell_type": "code",
   "execution_count": 35,
   "id": "9f34574c",
   "metadata": {},
   "outputs": [],
   "source": [
    "from transformers import pipeline"
   ]
  },
  {
   "cell_type": "code",
   "execution_count": 36,
   "id": "58cb05fa",
   "metadata": {},
   "outputs": [
    {
     "ename": "OSError",
     "evalue": "We couldn't connect to 'https://huggingface.co' to load this file, couldn't find it in the cached files and it looks like Cybernetyx/TARS_v0.2_QZ_ZS_1K is not the path to a directory containing a file named config.json.\nCheckout your internet connection or see how to run the library in offline mode at 'https://huggingface.co/docs/transformers/installation#offline-mode'.",
     "output_type": "error",
     "traceback": [
      "\u001b[0;31m---------------------------------------------------------------------------\u001b[0m",
      "\u001b[0;31mOSError\u001b[0m                                   Traceback (most recent call last)",
      "File \u001b[0;32m~/.pyenv/versions/3.10.6/envs/JC/lib/python3.10/site-packages/urllib3/connection.py:174\u001b[0m, in \u001b[0;36mHTTPConnection._new_conn\u001b[0;34m(self)\u001b[0m\n\u001b[1;32m    173\u001b[0m \u001b[38;5;28;01mtry\u001b[39;00m:\n\u001b[0;32m--> 174\u001b[0m     conn \u001b[38;5;241m=\u001b[39m \u001b[43mconnection\u001b[49m\u001b[38;5;241;43m.\u001b[39;49m\u001b[43mcreate_connection\u001b[49m\u001b[43m(\u001b[49m\n\u001b[1;32m    175\u001b[0m \u001b[43m        \u001b[49m\u001b[43m(\u001b[49m\u001b[38;5;28;43mself\u001b[39;49m\u001b[38;5;241;43m.\u001b[39;49m\u001b[43m_dns_host\u001b[49m\u001b[43m,\u001b[49m\u001b[43m \u001b[49m\u001b[38;5;28;43mself\u001b[39;49m\u001b[38;5;241;43m.\u001b[39;49m\u001b[43mport\u001b[49m\u001b[43m)\u001b[49m\u001b[43m,\u001b[49m\u001b[43m \u001b[49m\u001b[38;5;28;43mself\u001b[39;49m\u001b[38;5;241;43m.\u001b[39;49m\u001b[43mtimeout\u001b[49m\u001b[43m,\u001b[49m\u001b[43m \u001b[49m\u001b[38;5;241;43m*\u001b[39;49m\u001b[38;5;241;43m*\u001b[39;49m\u001b[43mextra_kw\u001b[49m\n\u001b[1;32m    176\u001b[0m \u001b[43m    \u001b[49m\u001b[43m)\u001b[49m\n\u001b[1;32m    178\u001b[0m \u001b[38;5;28;01mexcept\u001b[39;00m SocketTimeout:\n",
      "File \u001b[0;32m~/.pyenv/versions/3.10.6/envs/JC/lib/python3.10/site-packages/urllib3/util/connection.py:95\u001b[0m, in \u001b[0;36mcreate_connection\u001b[0;34m(address, timeout, source_address, socket_options)\u001b[0m\n\u001b[1;32m     94\u001b[0m \u001b[38;5;28;01mif\u001b[39;00m err \u001b[38;5;129;01mis\u001b[39;00m \u001b[38;5;129;01mnot\u001b[39;00m \u001b[38;5;28;01mNone\u001b[39;00m:\n\u001b[0;32m---> 95\u001b[0m     \u001b[38;5;28;01mraise\u001b[39;00m err\n\u001b[1;32m     97\u001b[0m \u001b[38;5;28;01mraise\u001b[39;00m socket\u001b[38;5;241m.\u001b[39merror(\u001b[38;5;124m\"\u001b[39m\u001b[38;5;124mgetaddrinfo returns an empty list\u001b[39m\u001b[38;5;124m\"\u001b[39m)\n",
      "File \u001b[0;32m~/.pyenv/versions/3.10.6/envs/JC/lib/python3.10/site-packages/urllib3/util/connection.py:85\u001b[0m, in \u001b[0;36mcreate_connection\u001b[0;34m(address, timeout, source_address, socket_options)\u001b[0m\n\u001b[1;32m     84\u001b[0m     sock\u001b[38;5;241m.\u001b[39mbind(source_address)\n\u001b[0;32m---> 85\u001b[0m \u001b[43msock\u001b[49m\u001b[38;5;241;43m.\u001b[39;49m\u001b[43mconnect\u001b[49m\u001b[43m(\u001b[49m\u001b[43msa\u001b[49m\u001b[43m)\u001b[49m\n\u001b[1;32m     86\u001b[0m \u001b[38;5;28;01mreturn\u001b[39;00m sock\n",
      "\u001b[0;31mOSError\u001b[0m: [Errno 101] Network is unreachable",
      "\nDuring handling of the above exception, another exception occurred:\n",
      "\u001b[0;31mNewConnectionError\u001b[0m                        Traceback (most recent call last)",
      "File \u001b[0;32m~/.pyenv/versions/3.10.6/envs/JC/lib/python3.10/site-packages/urllib3/connectionpool.py:703\u001b[0m, in \u001b[0;36mHTTPConnectionPool.urlopen\u001b[0;34m(self, method, url, body, headers, retries, redirect, assert_same_host, timeout, pool_timeout, release_conn, chunked, body_pos, **response_kw)\u001b[0m\n\u001b[1;32m    702\u001b[0m \u001b[38;5;66;03m# Make the request on the httplib connection object.\u001b[39;00m\n\u001b[0;32m--> 703\u001b[0m httplib_response \u001b[38;5;241m=\u001b[39m \u001b[38;5;28;43mself\u001b[39;49m\u001b[38;5;241;43m.\u001b[39;49m\u001b[43m_make_request\u001b[49m\u001b[43m(\u001b[49m\n\u001b[1;32m    704\u001b[0m \u001b[43m    \u001b[49m\u001b[43mconn\u001b[49m\u001b[43m,\u001b[49m\n\u001b[1;32m    705\u001b[0m \u001b[43m    \u001b[49m\u001b[43mmethod\u001b[49m\u001b[43m,\u001b[49m\n\u001b[1;32m    706\u001b[0m \u001b[43m    \u001b[49m\u001b[43murl\u001b[49m\u001b[43m,\u001b[49m\n\u001b[1;32m    707\u001b[0m \u001b[43m    \u001b[49m\u001b[43mtimeout\u001b[49m\u001b[38;5;241;43m=\u001b[39;49m\u001b[43mtimeout_obj\u001b[49m\u001b[43m,\u001b[49m\n\u001b[1;32m    708\u001b[0m \u001b[43m    \u001b[49m\u001b[43mbody\u001b[49m\u001b[38;5;241;43m=\u001b[39;49m\u001b[43mbody\u001b[49m\u001b[43m,\u001b[49m\n\u001b[1;32m    709\u001b[0m \u001b[43m    \u001b[49m\u001b[43mheaders\u001b[49m\u001b[38;5;241;43m=\u001b[39;49m\u001b[43mheaders\u001b[49m\u001b[43m,\u001b[49m\n\u001b[1;32m    710\u001b[0m \u001b[43m    \u001b[49m\u001b[43mchunked\u001b[49m\u001b[38;5;241;43m=\u001b[39;49m\u001b[43mchunked\u001b[49m\u001b[43m,\u001b[49m\n\u001b[1;32m    711\u001b[0m \u001b[43m\u001b[49m\u001b[43m)\u001b[49m\n\u001b[1;32m    713\u001b[0m \u001b[38;5;66;03m# If we're going to release the connection in ``finally:``, then\u001b[39;00m\n\u001b[1;32m    714\u001b[0m \u001b[38;5;66;03m# the response doesn't need to know about the connection. Otherwise\u001b[39;00m\n\u001b[1;32m    715\u001b[0m \u001b[38;5;66;03m# it will also try to release it and we'll have a double-release\u001b[39;00m\n\u001b[1;32m    716\u001b[0m \u001b[38;5;66;03m# mess.\u001b[39;00m\n",
      "File \u001b[0;32m~/.pyenv/versions/3.10.6/envs/JC/lib/python3.10/site-packages/urllib3/connectionpool.py:386\u001b[0m, in \u001b[0;36mHTTPConnectionPool._make_request\u001b[0;34m(self, conn, method, url, timeout, chunked, **httplib_request_kw)\u001b[0m\n\u001b[1;32m    385\u001b[0m \u001b[38;5;28;01mtry\u001b[39;00m:\n\u001b[0;32m--> 386\u001b[0m     \u001b[38;5;28;43mself\u001b[39;49m\u001b[38;5;241;43m.\u001b[39;49m\u001b[43m_validate_conn\u001b[49m\u001b[43m(\u001b[49m\u001b[43mconn\u001b[49m\u001b[43m)\u001b[49m\n\u001b[1;32m    387\u001b[0m \u001b[38;5;28;01mexcept\u001b[39;00m (SocketTimeout, BaseSSLError) \u001b[38;5;28;01mas\u001b[39;00m e:\n\u001b[1;32m    388\u001b[0m     \u001b[38;5;66;03m# Py2 raises this as a BaseSSLError, Py3 raises it as socket timeout.\u001b[39;00m\n",
      "File \u001b[0;32m~/.pyenv/versions/3.10.6/envs/JC/lib/python3.10/site-packages/urllib3/connectionpool.py:1042\u001b[0m, in \u001b[0;36mHTTPSConnectionPool._validate_conn\u001b[0;34m(self, conn)\u001b[0m\n\u001b[1;32m   1041\u001b[0m \u001b[38;5;28;01mif\u001b[39;00m \u001b[38;5;129;01mnot\u001b[39;00m \u001b[38;5;28mgetattr\u001b[39m(conn, \u001b[38;5;124m\"\u001b[39m\u001b[38;5;124msock\u001b[39m\u001b[38;5;124m\"\u001b[39m, \u001b[38;5;28;01mNone\u001b[39;00m):  \u001b[38;5;66;03m# AppEngine might not have  `.sock`\u001b[39;00m\n\u001b[0;32m-> 1042\u001b[0m     \u001b[43mconn\u001b[49m\u001b[38;5;241;43m.\u001b[39;49m\u001b[43mconnect\u001b[49m\u001b[43m(\u001b[49m\u001b[43m)\u001b[49m\n\u001b[1;32m   1044\u001b[0m \u001b[38;5;28;01mif\u001b[39;00m \u001b[38;5;129;01mnot\u001b[39;00m conn\u001b[38;5;241m.\u001b[39mis_verified:\n",
      "File \u001b[0;32m~/.pyenv/versions/3.10.6/envs/JC/lib/python3.10/site-packages/urllib3/connection.py:358\u001b[0m, in \u001b[0;36mHTTPSConnection.connect\u001b[0;34m(self)\u001b[0m\n\u001b[1;32m    356\u001b[0m \u001b[38;5;28;01mdef\u001b[39;00m \u001b[38;5;21mconnect\u001b[39m(\u001b[38;5;28mself\u001b[39m):\n\u001b[1;32m    357\u001b[0m     \u001b[38;5;66;03m# Add certificate verification\u001b[39;00m\n\u001b[0;32m--> 358\u001b[0m     \u001b[38;5;28mself\u001b[39m\u001b[38;5;241m.\u001b[39msock \u001b[38;5;241m=\u001b[39m conn \u001b[38;5;241m=\u001b[39m \u001b[38;5;28;43mself\u001b[39;49m\u001b[38;5;241;43m.\u001b[39;49m\u001b[43m_new_conn\u001b[49m\u001b[43m(\u001b[49m\u001b[43m)\u001b[49m\n\u001b[1;32m    359\u001b[0m     hostname \u001b[38;5;241m=\u001b[39m \u001b[38;5;28mself\u001b[39m\u001b[38;5;241m.\u001b[39mhost\n",
      "File \u001b[0;32m~/.pyenv/versions/3.10.6/envs/JC/lib/python3.10/site-packages/urllib3/connection.py:186\u001b[0m, in \u001b[0;36mHTTPConnection._new_conn\u001b[0;34m(self)\u001b[0m\n\u001b[1;32m    185\u001b[0m \u001b[38;5;28;01mexcept\u001b[39;00m SocketError \u001b[38;5;28;01mas\u001b[39;00m e:\n\u001b[0;32m--> 186\u001b[0m     \u001b[38;5;28;01mraise\u001b[39;00m NewConnectionError(\n\u001b[1;32m    187\u001b[0m         \u001b[38;5;28mself\u001b[39m, \u001b[38;5;124m\"\u001b[39m\u001b[38;5;124mFailed to establish a new connection: \u001b[39m\u001b[38;5;132;01m%s\u001b[39;00m\u001b[38;5;124m\"\u001b[39m \u001b[38;5;241m%\u001b[39m e\n\u001b[1;32m    188\u001b[0m     )\n\u001b[1;32m    190\u001b[0m \u001b[38;5;28;01mreturn\u001b[39;00m conn\n",
      "\u001b[0;31mNewConnectionError\u001b[0m: <urllib3.connection.HTTPSConnection object at 0x7f5ba3908eb0>: Failed to establish a new connection: [Errno 101] Network is unreachable",
      "\nDuring handling of the above exception, another exception occurred:\n",
      "\u001b[0;31mMaxRetryError\u001b[0m                             Traceback (most recent call last)",
      "File \u001b[0;32m~/.pyenv/versions/3.10.6/envs/JC/lib/python3.10/site-packages/requests/adapters.py:489\u001b[0m, in \u001b[0;36mHTTPAdapter.send\u001b[0;34m(self, request, stream, timeout, verify, cert, proxies)\u001b[0m\n\u001b[1;32m    488\u001b[0m \u001b[38;5;28;01mif\u001b[39;00m \u001b[38;5;129;01mnot\u001b[39;00m chunked:\n\u001b[0;32m--> 489\u001b[0m     resp \u001b[38;5;241m=\u001b[39m \u001b[43mconn\u001b[49m\u001b[38;5;241;43m.\u001b[39;49m\u001b[43murlopen\u001b[49m\u001b[43m(\u001b[49m\n\u001b[1;32m    490\u001b[0m \u001b[43m        \u001b[49m\u001b[43mmethod\u001b[49m\u001b[38;5;241;43m=\u001b[39;49m\u001b[43mrequest\u001b[49m\u001b[38;5;241;43m.\u001b[39;49m\u001b[43mmethod\u001b[49m\u001b[43m,\u001b[49m\n\u001b[1;32m    491\u001b[0m \u001b[43m        \u001b[49m\u001b[43murl\u001b[49m\u001b[38;5;241;43m=\u001b[39;49m\u001b[43murl\u001b[49m\u001b[43m,\u001b[49m\n\u001b[1;32m    492\u001b[0m \u001b[43m        \u001b[49m\u001b[43mbody\u001b[49m\u001b[38;5;241;43m=\u001b[39;49m\u001b[43mrequest\u001b[49m\u001b[38;5;241;43m.\u001b[39;49m\u001b[43mbody\u001b[49m\u001b[43m,\u001b[49m\n\u001b[1;32m    493\u001b[0m \u001b[43m        \u001b[49m\u001b[43mheaders\u001b[49m\u001b[38;5;241;43m=\u001b[39;49m\u001b[43mrequest\u001b[49m\u001b[38;5;241;43m.\u001b[39;49m\u001b[43mheaders\u001b[49m\u001b[43m,\u001b[49m\n\u001b[1;32m    494\u001b[0m \u001b[43m        \u001b[49m\u001b[43mredirect\u001b[49m\u001b[38;5;241;43m=\u001b[39;49m\u001b[38;5;28;43;01mFalse\u001b[39;49;00m\u001b[43m,\u001b[49m\n\u001b[1;32m    495\u001b[0m \u001b[43m        \u001b[49m\u001b[43massert_same_host\u001b[49m\u001b[38;5;241;43m=\u001b[39;49m\u001b[38;5;28;43;01mFalse\u001b[39;49;00m\u001b[43m,\u001b[49m\n\u001b[1;32m    496\u001b[0m \u001b[43m        \u001b[49m\u001b[43mpreload_content\u001b[49m\u001b[38;5;241;43m=\u001b[39;49m\u001b[38;5;28;43;01mFalse\u001b[39;49;00m\u001b[43m,\u001b[49m\n\u001b[1;32m    497\u001b[0m \u001b[43m        \u001b[49m\u001b[43mdecode_content\u001b[49m\u001b[38;5;241;43m=\u001b[39;49m\u001b[38;5;28;43;01mFalse\u001b[39;49;00m\u001b[43m,\u001b[49m\n\u001b[1;32m    498\u001b[0m \u001b[43m        \u001b[49m\u001b[43mretries\u001b[49m\u001b[38;5;241;43m=\u001b[39;49m\u001b[38;5;28;43mself\u001b[39;49m\u001b[38;5;241;43m.\u001b[39;49m\u001b[43mmax_retries\u001b[49m\u001b[43m,\u001b[49m\n\u001b[1;32m    499\u001b[0m \u001b[43m        \u001b[49m\u001b[43mtimeout\u001b[49m\u001b[38;5;241;43m=\u001b[39;49m\u001b[43mtimeout\u001b[49m\u001b[43m,\u001b[49m\n\u001b[1;32m    500\u001b[0m \u001b[43m    \u001b[49m\u001b[43m)\u001b[49m\n\u001b[1;32m    502\u001b[0m \u001b[38;5;66;03m# Send the request.\u001b[39;00m\n\u001b[1;32m    503\u001b[0m \u001b[38;5;28;01melse\u001b[39;00m:\n",
      "File \u001b[0;32m~/.pyenv/versions/3.10.6/envs/JC/lib/python3.10/site-packages/urllib3/connectionpool.py:787\u001b[0m, in \u001b[0;36mHTTPConnectionPool.urlopen\u001b[0;34m(self, method, url, body, headers, retries, redirect, assert_same_host, timeout, pool_timeout, release_conn, chunked, body_pos, **response_kw)\u001b[0m\n\u001b[1;32m    785\u001b[0m     e \u001b[38;5;241m=\u001b[39m ProtocolError(\u001b[38;5;124m\"\u001b[39m\u001b[38;5;124mConnection aborted.\u001b[39m\u001b[38;5;124m\"\u001b[39m, e)\n\u001b[0;32m--> 787\u001b[0m retries \u001b[38;5;241m=\u001b[39m \u001b[43mretries\u001b[49m\u001b[38;5;241;43m.\u001b[39;49m\u001b[43mincrement\u001b[49m\u001b[43m(\u001b[49m\n\u001b[1;32m    788\u001b[0m \u001b[43m    \u001b[49m\u001b[43mmethod\u001b[49m\u001b[43m,\u001b[49m\u001b[43m \u001b[49m\u001b[43murl\u001b[49m\u001b[43m,\u001b[49m\u001b[43m \u001b[49m\u001b[43merror\u001b[49m\u001b[38;5;241;43m=\u001b[39;49m\u001b[43me\u001b[49m\u001b[43m,\u001b[49m\u001b[43m \u001b[49m\u001b[43m_pool\u001b[49m\u001b[38;5;241;43m=\u001b[39;49m\u001b[38;5;28;43mself\u001b[39;49m\u001b[43m,\u001b[49m\u001b[43m \u001b[49m\u001b[43m_stacktrace\u001b[49m\u001b[38;5;241;43m=\u001b[39;49m\u001b[43msys\u001b[49m\u001b[38;5;241;43m.\u001b[39;49m\u001b[43mexc_info\u001b[49m\u001b[43m(\u001b[49m\u001b[43m)\u001b[49m\u001b[43m[\u001b[49m\u001b[38;5;241;43m2\u001b[39;49m\u001b[43m]\u001b[49m\n\u001b[1;32m    789\u001b[0m \u001b[43m\u001b[49m\u001b[43m)\u001b[49m\n\u001b[1;32m    790\u001b[0m retries\u001b[38;5;241m.\u001b[39msleep()\n",
      "File \u001b[0;32m~/.pyenv/versions/3.10.6/envs/JC/lib/python3.10/site-packages/urllib3/util/retry.py:592\u001b[0m, in \u001b[0;36mRetry.increment\u001b[0;34m(self, method, url, response, error, _pool, _stacktrace)\u001b[0m\n\u001b[1;32m    591\u001b[0m \u001b[38;5;28;01mif\u001b[39;00m new_retry\u001b[38;5;241m.\u001b[39mis_exhausted():\n\u001b[0;32m--> 592\u001b[0m     \u001b[38;5;28;01mraise\u001b[39;00m MaxRetryError(_pool, url, error \u001b[38;5;129;01mor\u001b[39;00m ResponseError(cause))\n\u001b[1;32m    594\u001b[0m log\u001b[38;5;241m.\u001b[39mdebug(\u001b[38;5;124m\"\u001b[39m\u001b[38;5;124mIncremented Retry for (url=\u001b[39m\u001b[38;5;124m'\u001b[39m\u001b[38;5;132;01m%s\u001b[39;00m\u001b[38;5;124m'\u001b[39m\u001b[38;5;124m): \u001b[39m\u001b[38;5;132;01m%r\u001b[39;00m\u001b[38;5;124m\"\u001b[39m, url, new_retry)\n",
      "\u001b[0;31mMaxRetryError\u001b[0m: HTTPSConnectionPool(host='huggingface.co', port=443): Max retries exceeded with url: /Cybernetyx/TARS_v0.2_QZ_ZS_1K/resolve/main/config.json (Caused by NewConnectionError('<urllib3.connection.HTTPSConnection object at 0x7f5ba3908eb0>: Failed to establish a new connection: [Errno 101] Network is unreachable'))",
      "\nDuring handling of the above exception, another exception occurred:\n",
      "\u001b[0;31mConnectionError\u001b[0m                           Traceback (most recent call last)",
      "File \u001b[0;32m~/.pyenv/versions/3.10.6/envs/JC/lib/python3.10/site-packages/huggingface_hub/file_download.py:1238\u001b[0m, in \u001b[0;36mhf_hub_download\u001b[0;34m(repo_id, filename, subfolder, repo_type, revision, library_name, library_version, cache_dir, local_dir, local_dir_use_symlinks, user_agent, force_download, force_filename, proxies, etag_timeout, resume_download, token, local_files_only, legacy_cache_layout, endpoint)\u001b[0m\n\u001b[1;32m   1237\u001b[0m \u001b[38;5;28;01mtry\u001b[39;00m:\n\u001b[0;32m-> 1238\u001b[0m     metadata \u001b[38;5;241m=\u001b[39m \u001b[43mget_hf_file_metadata\u001b[49m\u001b[43m(\u001b[49m\n\u001b[1;32m   1239\u001b[0m \u001b[43m        \u001b[49m\u001b[43murl\u001b[49m\u001b[38;5;241;43m=\u001b[39;49m\u001b[43murl\u001b[49m\u001b[43m,\u001b[49m\n\u001b[1;32m   1240\u001b[0m \u001b[43m        \u001b[49m\u001b[43mtoken\u001b[49m\u001b[38;5;241;43m=\u001b[39;49m\u001b[43mtoken\u001b[49m\u001b[43m,\u001b[49m\n\u001b[1;32m   1241\u001b[0m \u001b[43m        \u001b[49m\u001b[43mproxies\u001b[49m\u001b[38;5;241;43m=\u001b[39;49m\u001b[43mproxies\u001b[49m\u001b[43m,\u001b[49m\n\u001b[1;32m   1242\u001b[0m \u001b[43m        \u001b[49m\u001b[43mtimeout\u001b[49m\u001b[38;5;241;43m=\u001b[39;49m\u001b[43metag_timeout\u001b[49m\u001b[43m,\u001b[49m\n\u001b[1;32m   1243\u001b[0m \u001b[43m        \u001b[49m\u001b[43mlibrary_name\u001b[49m\u001b[38;5;241;43m=\u001b[39;49m\u001b[43mlibrary_name\u001b[49m\u001b[43m,\u001b[49m\n\u001b[1;32m   1244\u001b[0m \u001b[43m        \u001b[49m\u001b[43mlibrary_version\u001b[49m\u001b[38;5;241;43m=\u001b[39;49m\u001b[43mlibrary_version\u001b[49m\u001b[43m,\u001b[49m\n\u001b[1;32m   1245\u001b[0m \u001b[43m        \u001b[49m\u001b[43muser_agent\u001b[49m\u001b[38;5;241;43m=\u001b[39;49m\u001b[43muser_agent\u001b[49m\u001b[43m,\u001b[49m\n\u001b[1;32m   1246\u001b[0m \u001b[43m    \u001b[49m\u001b[43m)\u001b[49m\n\u001b[1;32m   1247\u001b[0m \u001b[38;5;28;01mexcept\u001b[39;00m EntryNotFoundError \u001b[38;5;28;01mas\u001b[39;00m http_error:\n\u001b[1;32m   1248\u001b[0m     \u001b[38;5;66;03m# Cache the non-existence of the file and raise\u001b[39;00m\n",
      "File \u001b[0;32m~/.pyenv/versions/3.10.6/envs/JC/lib/python3.10/site-packages/huggingface_hub/utils/_validators.py:118\u001b[0m, in \u001b[0;36mvalidate_hf_hub_args.<locals>._inner_fn\u001b[0;34m(*args, **kwargs)\u001b[0m\n\u001b[1;32m    116\u001b[0m     kwargs \u001b[38;5;241m=\u001b[39m smoothly_deprecate_use_auth_token(fn_name\u001b[38;5;241m=\u001b[39mfn\u001b[38;5;241m.\u001b[39m\u001b[38;5;18m__name__\u001b[39m, has_token\u001b[38;5;241m=\u001b[39mhas_token, kwargs\u001b[38;5;241m=\u001b[39mkwargs)\n\u001b[0;32m--> 118\u001b[0m \u001b[38;5;28;01mreturn\u001b[39;00m \u001b[43mfn\u001b[49m\u001b[43m(\u001b[49m\u001b[38;5;241;43m*\u001b[39;49m\u001b[43margs\u001b[49m\u001b[43m,\u001b[49m\u001b[43m \u001b[49m\u001b[38;5;241;43m*\u001b[39;49m\u001b[38;5;241;43m*\u001b[39;49m\u001b[43mkwargs\u001b[49m\u001b[43m)\u001b[49m\n",
      "File \u001b[0;32m~/.pyenv/versions/3.10.6/envs/JC/lib/python3.10/site-packages/huggingface_hub/file_download.py:1631\u001b[0m, in \u001b[0;36mget_hf_file_metadata\u001b[0;34m(url, token, proxies, timeout, library_name, library_version, user_agent)\u001b[0m\n\u001b[1;32m   1630\u001b[0m \u001b[38;5;66;03m# Retrieve metadata\u001b[39;00m\n\u001b[0;32m-> 1631\u001b[0m r \u001b[38;5;241m=\u001b[39m \u001b[43m_request_wrapper\u001b[49m\u001b[43m(\u001b[49m\n\u001b[1;32m   1632\u001b[0m \u001b[43m    \u001b[49m\u001b[43mmethod\u001b[49m\u001b[38;5;241;43m=\u001b[39;49m\u001b[38;5;124;43m\"\u001b[39;49m\u001b[38;5;124;43mHEAD\u001b[39;49m\u001b[38;5;124;43m\"\u001b[39;49m\u001b[43m,\u001b[49m\n\u001b[1;32m   1633\u001b[0m \u001b[43m    \u001b[49m\u001b[43murl\u001b[49m\u001b[38;5;241;43m=\u001b[39;49m\u001b[43murl\u001b[49m\u001b[43m,\u001b[49m\n\u001b[1;32m   1634\u001b[0m \u001b[43m    \u001b[49m\u001b[43mheaders\u001b[49m\u001b[38;5;241;43m=\u001b[39;49m\u001b[43mheaders\u001b[49m\u001b[43m,\u001b[49m\n\u001b[1;32m   1635\u001b[0m \u001b[43m    \u001b[49m\u001b[43mallow_redirects\u001b[49m\u001b[38;5;241;43m=\u001b[39;49m\u001b[38;5;28;43;01mFalse\u001b[39;49;00m\u001b[43m,\u001b[49m\n\u001b[1;32m   1636\u001b[0m \u001b[43m    \u001b[49m\u001b[43mfollow_relative_redirects\u001b[49m\u001b[38;5;241;43m=\u001b[39;49m\u001b[38;5;28;43;01mTrue\u001b[39;49;00m\u001b[43m,\u001b[49m\n\u001b[1;32m   1637\u001b[0m \u001b[43m    \u001b[49m\u001b[43mproxies\u001b[49m\u001b[38;5;241;43m=\u001b[39;49m\u001b[43mproxies\u001b[49m\u001b[43m,\u001b[49m\n\u001b[1;32m   1638\u001b[0m \u001b[43m    \u001b[49m\u001b[43mtimeout\u001b[49m\u001b[38;5;241;43m=\u001b[39;49m\u001b[43mtimeout\u001b[49m\u001b[43m,\u001b[49m\n\u001b[1;32m   1639\u001b[0m \u001b[43m\u001b[49m\u001b[43m)\u001b[49m\n\u001b[1;32m   1640\u001b[0m hf_raise_for_status(r)\n",
      "File \u001b[0;32m~/.pyenv/versions/3.10.6/envs/JC/lib/python3.10/site-packages/huggingface_hub/file_download.py:385\u001b[0m, in \u001b[0;36m_request_wrapper\u001b[0;34m(method, url, follow_relative_redirects, **params)\u001b[0m\n\u001b[1;32m    384\u001b[0m \u001b[38;5;28;01mif\u001b[39;00m follow_relative_redirects:\n\u001b[0;32m--> 385\u001b[0m     response \u001b[38;5;241m=\u001b[39m \u001b[43m_request_wrapper\u001b[49m\u001b[43m(\u001b[49m\n\u001b[1;32m    386\u001b[0m \u001b[43m        \u001b[49m\u001b[43mmethod\u001b[49m\u001b[38;5;241;43m=\u001b[39;49m\u001b[43mmethod\u001b[49m\u001b[43m,\u001b[49m\n\u001b[1;32m    387\u001b[0m \u001b[43m        \u001b[49m\u001b[43murl\u001b[49m\u001b[38;5;241;43m=\u001b[39;49m\u001b[43murl\u001b[49m\u001b[43m,\u001b[49m\n\u001b[1;32m    388\u001b[0m \u001b[43m        \u001b[49m\u001b[43mfollow_relative_redirects\u001b[49m\u001b[38;5;241;43m=\u001b[39;49m\u001b[38;5;28;43;01mFalse\u001b[39;49;00m\u001b[43m,\u001b[49m\n\u001b[1;32m    389\u001b[0m \u001b[43m        \u001b[49m\u001b[38;5;241;43m*\u001b[39;49m\u001b[38;5;241;43m*\u001b[39;49m\u001b[43mparams\u001b[49m\u001b[43m,\u001b[49m\n\u001b[1;32m    390\u001b[0m \u001b[43m    \u001b[49m\u001b[43m)\u001b[49m\n\u001b[1;32m    392\u001b[0m     \u001b[38;5;66;03m# If redirection, we redirect only relative paths.\u001b[39;00m\n\u001b[1;32m    393\u001b[0m     \u001b[38;5;66;03m# This is useful in case of a renamed repository.\u001b[39;00m\n",
      "File \u001b[0;32m~/.pyenv/versions/3.10.6/envs/JC/lib/python3.10/site-packages/huggingface_hub/file_download.py:408\u001b[0m, in \u001b[0;36m_request_wrapper\u001b[0;34m(method, url, follow_relative_redirects, **params)\u001b[0m\n\u001b[1;32m    407\u001b[0m \u001b[38;5;66;03m# Perform request and return if status_code is not in the retry list.\u001b[39;00m\n\u001b[0;32m--> 408\u001b[0m response \u001b[38;5;241m=\u001b[39m \u001b[43mget_session\u001b[49m\u001b[43m(\u001b[49m\u001b[43m)\u001b[49m\u001b[38;5;241;43m.\u001b[39;49m\u001b[43mrequest\u001b[49m\u001b[43m(\u001b[49m\u001b[43mmethod\u001b[49m\u001b[38;5;241;43m=\u001b[39;49m\u001b[43mmethod\u001b[49m\u001b[43m,\u001b[49m\u001b[43m \u001b[49m\u001b[43murl\u001b[49m\u001b[38;5;241;43m=\u001b[39;49m\u001b[43murl\u001b[49m\u001b[43m,\u001b[49m\u001b[43m \u001b[49m\u001b[38;5;241;43m*\u001b[39;49m\u001b[38;5;241;43m*\u001b[39;49m\u001b[43mparams\u001b[49m\u001b[43m)\u001b[49m\n\u001b[1;32m    409\u001b[0m hf_raise_for_status(response)\n",
      "File \u001b[0;32m~/.pyenv/versions/3.10.6/envs/JC/lib/python3.10/site-packages/requests/sessions.py:587\u001b[0m, in \u001b[0;36mSession.request\u001b[0;34m(self, method, url, params, data, headers, cookies, files, auth, timeout, allow_redirects, proxies, hooks, stream, verify, cert, json)\u001b[0m\n\u001b[1;32m    586\u001b[0m send_kwargs\u001b[38;5;241m.\u001b[39mupdate(settings)\n\u001b[0;32m--> 587\u001b[0m resp \u001b[38;5;241m=\u001b[39m \u001b[38;5;28;43mself\u001b[39;49m\u001b[38;5;241;43m.\u001b[39;49m\u001b[43msend\u001b[49m\u001b[43m(\u001b[49m\u001b[43mprep\u001b[49m\u001b[43m,\u001b[49m\u001b[43m \u001b[49m\u001b[38;5;241;43m*\u001b[39;49m\u001b[38;5;241;43m*\u001b[39;49m\u001b[43msend_kwargs\u001b[49m\u001b[43m)\u001b[49m\n\u001b[1;32m    589\u001b[0m \u001b[38;5;28;01mreturn\u001b[39;00m resp\n",
      "File \u001b[0;32m~/.pyenv/versions/3.10.6/envs/JC/lib/python3.10/site-packages/requests/sessions.py:701\u001b[0m, in \u001b[0;36mSession.send\u001b[0;34m(self, request, **kwargs)\u001b[0m\n\u001b[1;32m    700\u001b[0m \u001b[38;5;66;03m# Send the request\u001b[39;00m\n\u001b[0;32m--> 701\u001b[0m r \u001b[38;5;241m=\u001b[39m \u001b[43madapter\u001b[49m\u001b[38;5;241;43m.\u001b[39;49m\u001b[43msend\u001b[49m\u001b[43m(\u001b[49m\u001b[43mrequest\u001b[49m\u001b[43m,\u001b[49m\u001b[43m \u001b[49m\u001b[38;5;241;43m*\u001b[39;49m\u001b[38;5;241;43m*\u001b[39;49m\u001b[43mkwargs\u001b[49m\u001b[43m)\u001b[49m\n\u001b[1;32m    703\u001b[0m \u001b[38;5;66;03m# Total elapsed time of the request (approximately)\u001b[39;00m\n",
      "File \u001b[0;32m~/.pyenv/versions/3.10.6/envs/JC/lib/python3.10/site-packages/huggingface_hub/utils/_http.py:67\u001b[0m, in \u001b[0;36mUniqueRequestIdAdapter.send\u001b[0;34m(self, request, *args, **kwargs)\u001b[0m\n\u001b[1;32m     66\u001b[0m \u001b[38;5;28;01mtry\u001b[39;00m:\n\u001b[0;32m---> 67\u001b[0m     \u001b[38;5;28;01mreturn\u001b[39;00m \u001b[38;5;28;43msuper\u001b[39;49m\u001b[43m(\u001b[49m\u001b[43m)\u001b[49m\u001b[38;5;241;43m.\u001b[39;49m\u001b[43msend\u001b[49m\u001b[43m(\u001b[49m\u001b[43mrequest\u001b[49m\u001b[43m,\u001b[49m\u001b[43m \u001b[49m\u001b[38;5;241;43m*\u001b[39;49m\u001b[43margs\u001b[49m\u001b[43m,\u001b[49m\u001b[43m \u001b[49m\u001b[38;5;241;43m*\u001b[39;49m\u001b[38;5;241;43m*\u001b[39;49m\u001b[43mkwargs\u001b[49m\u001b[43m)\u001b[49m\n\u001b[1;32m     68\u001b[0m \u001b[38;5;28;01mexcept\u001b[39;00m requests\u001b[38;5;241m.\u001b[39mRequestException \u001b[38;5;28;01mas\u001b[39;00m e:\n",
      "File \u001b[0;32m~/.pyenv/versions/3.10.6/envs/JC/lib/python3.10/site-packages/requests/adapters.py:565\u001b[0m, in \u001b[0;36mHTTPAdapter.send\u001b[0;34m(self, request, stream, timeout, verify, cert, proxies)\u001b[0m\n\u001b[1;32m    563\u001b[0m         \u001b[38;5;28;01mraise\u001b[39;00m SSLError(e, request\u001b[38;5;241m=\u001b[39mrequest)\n\u001b[0;32m--> 565\u001b[0m     \u001b[38;5;28;01mraise\u001b[39;00m \u001b[38;5;167;01mConnectionError\u001b[39;00m(e, request\u001b[38;5;241m=\u001b[39mrequest)\n\u001b[1;32m    567\u001b[0m \u001b[38;5;28;01mexcept\u001b[39;00m ClosedPoolError \u001b[38;5;28;01mas\u001b[39;00m e:\n",
      "\u001b[0;31mConnectionError\u001b[0m: (MaxRetryError(\"HTTPSConnectionPool(host='huggingface.co', port=443): Max retries exceeded with url: /Cybernetyx/TARS_v0.2_QZ_ZS_1K/resolve/main/config.json (Caused by NewConnectionError('<urllib3.connection.HTTPSConnection object at 0x7f5ba3908eb0>: Failed to establish a new connection: [Errno 101] Network is unreachable'))\"), '(Request ID: 3125d648-babb-46ad-8022-c34f735f739f)')",
      "\nThe above exception was the direct cause of the following exception:\n",
      "\u001b[0;31mLocalEntryNotFoundError\u001b[0m                   Traceback (most recent call last)",
      "File \u001b[0;32m~/.pyenv/versions/3.10.6/envs/JC/lib/python3.10/site-packages/transformers/utils/hub.py:385\u001b[0m, in \u001b[0;36mcached_file\u001b[0;34m(path_or_repo_id, filename, cache_dir, force_download, resume_download, proxies, token, revision, local_files_only, subfolder, repo_type, user_agent, _raise_exceptions_for_missing_entries, _raise_exceptions_for_connection_errors, _commit_hash, **deprecated_kwargs)\u001b[0m\n\u001b[1;32m    383\u001b[0m \u001b[38;5;28;01mtry\u001b[39;00m:\n\u001b[1;32m    384\u001b[0m     \u001b[38;5;66;03m# Load from URL or cache if already cached\u001b[39;00m\n\u001b[0;32m--> 385\u001b[0m     resolved_file \u001b[38;5;241m=\u001b[39m \u001b[43mhf_hub_download\u001b[49m\u001b[43m(\u001b[49m\n\u001b[1;32m    386\u001b[0m \u001b[43m        \u001b[49m\u001b[43mpath_or_repo_id\u001b[49m\u001b[43m,\u001b[49m\n\u001b[1;32m    387\u001b[0m \u001b[43m        \u001b[49m\u001b[43mfilename\u001b[49m\u001b[43m,\u001b[49m\n\u001b[1;32m    388\u001b[0m \u001b[43m        \u001b[49m\u001b[43msubfolder\u001b[49m\u001b[38;5;241;43m=\u001b[39;49m\u001b[38;5;28;43;01mNone\u001b[39;49;00m\u001b[43m \u001b[49m\u001b[38;5;28;43;01mif\u001b[39;49;00m\u001b[43m \u001b[49m\u001b[38;5;28;43mlen\u001b[39;49m\u001b[43m(\u001b[49m\u001b[43msubfolder\u001b[49m\u001b[43m)\u001b[49m\u001b[43m \u001b[49m\u001b[38;5;241;43m==\u001b[39;49m\u001b[43m \u001b[49m\u001b[38;5;241;43m0\u001b[39;49m\u001b[43m \u001b[49m\u001b[38;5;28;43;01melse\u001b[39;49;00m\u001b[43m \u001b[49m\u001b[43msubfolder\u001b[49m\u001b[43m,\u001b[49m\n\u001b[1;32m    389\u001b[0m \u001b[43m        \u001b[49m\u001b[43mrepo_type\u001b[49m\u001b[38;5;241;43m=\u001b[39;49m\u001b[43mrepo_type\u001b[49m\u001b[43m,\u001b[49m\n\u001b[1;32m    390\u001b[0m \u001b[43m        \u001b[49m\u001b[43mrevision\u001b[49m\u001b[38;5;241;43m=\u001b[39;49m\u001b[43mrevision\u001b[49m\u001b[43m,\u001b[49m\n\u001b[1;32m    391\u001b[0m \u001b[43m        \u001b[49m\u001b[43mcache_dir\u001b[49m\u001b[38;5;241;43m=\u001b[39;49m\u001b[43mcache_dir\u001b[49m\u001b[43m,\u001b[49m\n\u001b[1;32m    392\u001b[0m \u001b[43m        \u001b[49m\u001b[43muser_agent\u001b[49m\u001b[38;5;241;43m=\u001b[39;49m\u001b[43muser_agent\u001b[49m\u001b[43m,\u001b[49m\n\u001b[1;32m    393\u001b[0m \u001b[43m        \u001b[49m\u001b[43mforce_download\u001b[49m\u001b[38;5;241;43m=\u001b[39;49m\u001b[43mforce_download\u001b[49m\u001b[43m,\u001b[49m\n\u001b[1;32m    394\u001b[0m \u001b[43m        \u001b[49m\u001b[43mproxies\u001b[49m\u001b[38;5;241;43m=\u001b[39;49m\u001b[43mproxies\u001b[49m\u001b[43m,\u001b[49m\n\u001b[1;32m    395\u001b[0m \u001b[43m        \u001b[49m\u001b[43mresume_download\u001b[49m\u001b[38;5;241;43m=\u001b[39;49m\u001b[43mresume_download\u001b[49m\u001b[43m,\u001b[49m\n\u001b[1;32m    396\u001b[0m \u001b[43m        \u001b[49m\u001b[43mtoken\u001b[49m\u001b[38;5;241;43m=\u001b[39;49m\u001b[43mtoken\u001b[49m\u001b[43m,\u001b[49m\n\u001b[1;32m    397\u001b[0m \u001b[43m        \u001b[49m\u001b[43mlocal_files_only\u001b[49m\u001b[38;5;241;43m=\u001b[39;49m\u001b[43mlocal_files_only\u001b[49m\u001b[43m,\u001b[49m\n\u001b[1;32m    398\u001b[0m \u001b[43m    \u001b[49m\u001b[43m)\u001b[49m\n\u001b[1;32m    399\u001b[0m \u001b[38;5;28;01mexcept\u001b[39;00m GatedRepoError \u001b[38;5;28;01mas\u001b[39;00m e:\n",
      "File \u001b[0;32m~/.pyenv/versions/3.10.6/envs/JC/lib/python3.10/site-packages/huggingface_hub/utils/_validators.py:118\u001b[0m, in \u001b[0;36mvalidate_hf_hub_args.<locals>._inner_fn\u001b[0;34m(*args, **kwargs)\u001b[0m\n\u001b[1;32m    116\u001b[0m     kwargs \u001b[38;5;241m=\u001b[39m smoothly_deprecate_use_auth_token(fn_name\u001b[38;5;241m=\u001b[39mfn\u001b[38;5;241m.\u001b[39m\u001b[38;5;18m__name__\u001b[39m, has_token\u001b[38;5;241m=\u001b[39mhas_token, kwargs\u001b[38;5;241m=\u001b[39mkwargs)\n\u001b[0;32m--> 118\u001b[0m \u001b[38;5;28;01mreturn\u001b[39;00m \u001b[43mfn\u001b[49m\u001b[43m(\u001b[49m\u001b[38;5;241;43m*\u001b[39;49m\u001b[43margs\u001b[49m\u001b[43m,\u001b[49m\u001b[43m \u001b[49m\u001b[38;5;241;43m*\u001b[39;49m\u001b[38;5;241;43m*\u001b[39;49m\u001b[43mkwargs\u001b[49m\u001b[43m)\u001b[49m\n",
      "File \u001b[0;32m~/.pyenv/versions/3.10.6/envs/JC/lib/python3.10/site-packages/huggingface_hub/file_download.py:1371\u001b[0m, in \u001b[0;36mhf_hub_download\u001b[0;34m(repo_id, filename, subfolder, repo_type, revision, library_name, library_version, cache_dir, local_dir, local_dir_use_symlinks, user_agent, force_download, force_filename, proxies, etag_timeout, resume_download, token, local_files_only, legacy_cache_layout, endpoint)\u001b[0m\n\u001b[1;32m   1369\u001b[0m     \u001b[38;5;28;01melse\u001b[39;00m:\n\u001b[1;32m   1370\u001b[0m         \u001b[38;5;66;03m# Otherwise: most likely a connection issue or Hub downtime => let's warn the user\u001b[39;00m\n\u001b[0;32m-> 1371\u001b[0m         \u001b[38;5;28;01mraise\u001b[39;00m LocalEntryNotFoundError(\n\u001b[1;32m   1372\u001b[0m             \u001b[38;5;124m\"\u001b[39m\u001b[38;5;124mAn error happened while trying to locate the file on the Hub and we cannot find the requested files\u001b[39m\u001b[38;5;124m\"\u001b[39m\n\u001b[1;32m   1373\u001b[0m             \u001b[38;5;124m\"\u001b[39m\u001b[38;5;124m in the local cache. Please check your connection and try again or make sure your Internet connection\u001b[39m\u001b[38;5;124m\"\u001b[39m\n\u001b[1;32m   1374\u001b[0m             \u001b[38;5;124m\"\u001b[39m\u001b[38;5;124m is on.\u001b[39m\u001b[38;5;124m\"\u001b[39m\n\u001b[1;32m   1375\u001b[0m         ) \u001b[38;5;28;01mfrom\u001b[39;00m \u001b[38;5;21;01mhead_call_error\u001b[39;00m\n\u001b[1;32m   1377\u001b[0m \u001b[38;5;66;03m# From now on, etag and commit_hash are not None.\u001b[39;00m\n",
      "\u001b[0;31mLocalEntryNotFoundError\u001b[0m: An error happened while trying to locate the file on the Hub and we cannot find the requested files in the local cache. Please check your connection and try again or make sure your Internet connection is on.",
      "\nThe above exception was the direct cause of the following exception:\n",
      "\u001b[0;31mOSError\u001b[0m                                   Traceback (most recent call last)",
      "Cell \u001b[0;32mIn [36], line 1\u001b[0m\n\u001b[0;32m----> 1\u001b[0m model \u001b[38;5;241m=\u001b[39m \u001b[43mpipeline\u001b[49m\u001b[43m(\u001b[49m\u001b[38;5;124;43m\"\u001b[39;49m\u001b[38;5;124;43mtext-generation\u001b[39;49m\u001b[38;5;124;43m\"\u001b[39;49m\u001b[43m,\u001b[49m\u001b[43m \u001b[49m\u001b[43mmodel\u001b[49m\u001b[38;5;241;43m=\u001b[39;49m\u001b[38;5;124;43m\"\u001b[39;49m\u001b[38;5;124;43mCybernetyx/TARS_v0.2_QZ_ZS_1K\u001b[39;49m\u001b[38;5;124;43m\"\u001b[39;49m\u001b[43m)\u001b[49m\n",
      "File \u001b[0;32m~/.pyenv/versions/3.10.6/envs/JC/lib/python3.10/site-packages/transformers/pipelines/__init__.py:782\u001b[0m, in \u001b[0;36mpipeline\u001b[0;34m(task, model, config, tokenizer, feature_extractor, image_processor, framework, revision, use_fast, token, device, device_map, torch_dtype, trust_remote_code, model_kwargs, pipeline_class, **kwargs)\u001b[0m\n\u001b[1;32m    779\u001b[0m                 adapter_config \u001b[38;5;241m=\u001b[39m json\u001b[38;5;241m.\u001b[39mload(f)\n\u001b[1;32m    780\u001b[0m                 model \u001b[38;5;241m=\u001b[39m adapter_config[\u001b[38;5;124m\"\u001b[39m\u001b[38;5;124mbase_model_name_or_path\u001b[39m\u001b[38;5;124m\"\u001b[39m]\n\u001b[0;32m--> 782\u001b[0m     config \u001b[38;5;241m=\u001b[39m \u001b[43mAutoConfig\u001b[49m\u001b[38;5;241;43m.\u001b[39;49m\u001b[43mfrom_pretrained\u001b[49m\u001b[43m(\u001b[49m\n\u001b[1;32m    783\u001b[0m \u001b[43m        \u001b[49m\u001b[43mmodel\u001b[49m\u001b[43m,\u001b[49m\u001b[43m \u001b[49m\u001b[43m_from_pipeline\u001b[49m\u001b[38;5;241;43m=\u001b[39;49m\u001b[43mtask\u001b[49m\u001b[43m,\u001b[49m\u001b[43m \u001b[49m\u001b[43mcode_revision\u001b[49m\u001b[38;5;241;43m=\u001b[39;49m\u001b[43mcode_revision\u001b[49m\u001b[43m,\u001b[49m\u001b[43m \u001b[49m\u001b[38;5;241;43m*\u001b[39;49m\u001b[38;5;241;43m*\u001b[39;49m\u001b[43mhub_kwargs\u001b[49m\u001b[43m,\u001b[49m\u001b[43m \u001b[49m\u001b[38;5;241;43m*\u001b[39;49m\u001b[38;5;241;43m*\u001b[39;49m\u001b[43mmodel_kwargs\u001b[49m\n\u001b[1;32m    784\u001b[0m \u001b[43m    \u001b[49m\u001b[43m)\u001b[49m\n\u001b[1;32m    785\u001b[0m     hub_kwargs[\u001b[38;5;124m\"\u001b[39m\u001b[38;5;124m_commit_hash\u001b[39m\u001b[38;5;124m\"\u001b[39m] \u001b[38;5;241m=\u001b[39m config\u001b[38;5;241m.\u001b[39m_commit_hash\n\u001b[1;32m    787\u001b[0m custom_tasks \u001b[38;5;241m=\u001b[39m {}\n",
      "File \u001b[0;32m~/.pyenv/versions/3.10.6/envs/JC/lib/python3.10/site-packages/transformers/models/auto/configuration_auto.py:1100\u001b[0m, in \u001b[0;36mAutoConfig.from_pretrained\u001b[0;34m(cls, pretrained_model_name_or_path, **kwargs)\u001b[0m\n\u001b[1;32m   1097\u001b[0m trust_remote_code \u001b[38;5;241m=\u001b[39m kwargs\u001b[38;5;241m.\u001b[39mpop(\u001b[38;5;124m\"\u001b[39m\u001b[38;5;124mtrust_remote_code\u001b[39m\u001b[38;5;124m\"\u001b[39m, \u001b[38;5;28;01mNone\u001b[39;00m)\n\u001b[1;32m   1098\u001b[0m code_revision \u001b[38;5;241m=\u001b[39m kwargs\u001b[38;5;241m.\u001b[39mpop(\u001b[38;5;124m\"\u001b[39m\u001b[38;5;124mcode_revision\u001b[39m\u001b[38;5;124m\"\u001b[39m, \u001b[38;5;28;01mNone\u001b[39;00m)\n\u001b[0;32m-> 1100\u001b[0m config_dict, unused_kwargs \u001b[38;5;241m=\u001b[39m \u001b[43mPretrainedConfig\u001b[49m\u001b[38;5;241;43m.\u001b[39;49m\u001b[43mget_config_dict\u001b[49m\u001b[43m(\u001b[49m\u001b[43mpretrained_model_name_or_path\u001b[49m\u001b[43m,\u001b[49m\u001b[43m \u001b[49m\u001b[38;5;241;43m*\u001b[39;49m\u001b[38;5;241;43m*\u001b[39;49m\u001b[43mkwargs\u001b[49m\u001b[43m)\u001b[49m\n\u001b[1;32m   1101\u001b[0m has_remote_code \u001b[38;5;241m=\u001b[39m \u001b[38;5;124m\"\u001b[39m\u001b[38;5;124mauto_map\u001b[39m\u001b[38;5;124m\"\u001b[39m \u001b[38;5;129;01min\u001b[39;00m config_dict \u001b[38;5;129;01mand\u001b[39;00m \u001b[38;5;124m\"\u001b[39m\u001b[38;5;124mAutoConfig\u001b[39m\u001b[38;5;124m\"\u001b[39m \u001b[38;5;129;01min\u001b[39;00m config_dict[\u001b[38;5;124m\"\u001b[39m\u001b[38;5;124mauto_map\u001b[39m\u001b[38;5;124m\"\u001b[39m]\n\u001b[1;32m   1102\u001b[0m has_local_code \u001b[38;5;241m=\u001b[39m \u001b[38;5;124m\"\u001b[39m\u001b[38;5;124mmodel_type\u001b[39m\u001b[38;5;124m\"\u001b[39m \u001b[38;5;129;01min\u001b[39;00m config_dict \u001b[38;5;129;01mand\u001b[39;00m config_dict[\u001b[38;5;124m\"\u001b[39m\u001b[38;5;124mmodel_type\u001b[39m\u001b[38;5;124m\"\u001b[39m] \u001b[38;5;129;01min\u001b[39;00m CONFIG_MAPPING\n",
      "File \u001b[0;32m~/.pyenv/versions/3.10.6/envs/JC/lib/python3.10/site-packages/transformers/configuration_utils.py:634\u001b[0m, in \u001b[0;36mPretrainedConfig.get_config_dict\u001b[0;34m(cls, pretrained_model_name_or_path, **kwargs)\u001b[0m\n\u001b[1;32m    632\u001b[0m original_kwargs \u001b[38;5;241m=\u001b[39m copy\u001b[38;5;241m.\u001b[39mdeepcopy(kwargs)\n\u001b[1;32m    633\u001b[0m \u001b[38;5;66;03m# Get config dict associated with the base config file\u001b[39;00m\n\u001b[0;32m--> 634\u001b[0m config_dict, kwargs \u001b[38;5;241m=\u001b[39m \u001b[38;5;28;43mcls\u001b[39;49m\u001b[38;5;241;43m.\u001b[39;49m\u001b[43m_get_config_dict\u001b[49m\u001b[43m(\u001b[49m\u001b[43mpretrained_model_name_or_path\u001b[49m\u001b[43m,\u001b[49m\u001b[43m \u001b[49m\u001b[38;5;241;43m*\u001b[39;49m\u001b[38;5;241;43m*\u001b[39;49m\u001b[43mkwargs\u001b[49m\u001b[43m)\u001b[49m\n\u001b[1;32m    635\u001b[0m \u001b[38;5;28;01mif\u001b[39;00m \u001b[38;5;124m\"\u001b[39m\u001b[38;5;124m_commit_hash\u001b[39m\u001b[38;5;124m\"\u001b[39m \u001b[38;5;129;01min\u001b[39;00m config_dict:\n\u001b[1;32m    636\u001b[0m     original_kwargs[\u001b[38;5;124m\"\u001b[39m\u001b[38;5;124m_commit_hash\u001b[39m\u001b[38;5;124m\"\u001b[39m] \u001b[38;5;241m=\u001b[39m config_dict[\u001b[38;5;124m\"\u001b[39m\u001b[38;5;124m_commit_hash\u001b[39m\u001b[38;5;124m\"\u001b[39m]\n",
      "File \u001b[0;32m~/.pyenv/versions/3.10.6/envs/JC/lib/python3.10/site-packages/transformers/configuration_utils.py:689\u001b[0m, in \u001b[0;36mPretrainedConfig._get_config_dict\u001b[0;34m(cls, pretrained_model_name_or_path, **kwargs)\u001b[0m\n\u001b[1;32m    685\u001b[0m configuration_file \u001b[38;5;241m=\u001b[39m kwargs\u001b[38;5;241m.\u001b[39mpop(\u001b[38;5;124m\"\u001b[39m\u001b[38;5;124m_configuration_file\u001b[39m\u001b[38;5;124m\"\u001b[39m, CONFIG_NAME)\n\u001b[1;32m    687\u001b[0m \u001b[38;5;28;01mtry\u001b[39;00m:\n\u001b[1;32m    688\u001b[0m     \u001b[38;5;66;03m# Load from local folder or from cache or download from model Hub and cache\u001b[39;00m\n\u001b[0;32m--> 689\u001b[0m     resolved_config_file \u001b[38;5;241m=\u001b[39m \u001b[43mcached_file\u001b[49m\u001b[43m(\u001b[49m\n\u001b[1;32m    690\u001b[0m \u001b[43m        \u001b[49m\u001b[43mpretrained_model_name_or_path\u001b[49m\u001b[43m,\u001b[49m\n\u001b[1;32m    691\u001b[0m \u001b[43m        \u001b[49m\u001b[43mconfiguration_file\u001b[49m\u001b[43m,\u001b[49m\n\u001b[1;32m    692\u001b[0m \u001b[43m        \u001b[49m\u001b[43mcache_dir\u001b[49m\u001b[38;5;241;43m=\u001b[39;49m\u001b[43mcache_dir\u001b[49m\u001b[43m,\u001b[49m\n\u001b[1;32m    693\u001b[0m \u001b[43m        \u001b[49m\u001b[43mforce_download\u001b[49m\u001b[38;5;241;43m=\u001b[39;49m\u001b[43mforce_download\u001b[49m\u001b[43m,\u001b[49m\n\u001b[1;32m    694\u001b[0m \u001b[43m        \u001b[49m\u001b[43mproxies\u001b[49m\u001b[38;5;241;43m=\u001b[39;49m\u001b[43mproxies\u001b[49m\u001b[43m,\u001b[49m\n\u001b[1;32m    695\u001b[0m \u001b[43m        \u001b[49m\u001b[43mresume_download\u001b[49m\u001b[38;5;241;43m=\u001b[39;49m\u001b[43mresume_download\u001b[49m\u001b[43m,\u001b[49m\n\u001b[1;32m    696\u001b[0m \u001b[43m        \u001b[49m\u001b[43mlocal_files_only\u001b[49m\u001b[38;5;241;43m=\u001b[39;49m\u001b[43mlocal_files_only\u001b[49m\u001b[43m,\u001b[49m\n\u001b[1;32m    697\u001b[0m \u001b[43m        \u001b[49m\u001b[43mtoken\u001b[49m\u001b[38;5;241;43m=\u001b[39;49m\u001b[43mtoken\u001b[49m\u001b[43m,\u001b[49m\n\u001b[1;32m    698\u001b[0m \u001b[43m        \u001b[49m\u001b[43muser_agent\u001b[49m\u001b[38;5;241;43m=\u001b[39;49m\u001b[43muser_agent\u001b[49m\u001b[43m,\u001b[49m\n\u001b[1;32m    699\u001b[0m \u001b[43m        \u001b[49m\u001b[43mrevision\u001b[49m\u001b[38;5;241;43m=\u001b[39;49m\u001b[43mrevision\u001b[49m\u001b[43m,\u001b[49m\n\u001b[1;32m    700\u001b[0m \u001b[43m        \u001b[49m\u001b[43msubfolder\u001b[49m\u001b[38;5;241;43m=\u001b[39;49m\u001b[43msubfolder\u001b[49m\u001b[43m,\u001b[49m\n\u001b[1;32m    701\u001b[0m \u001b[43m        \u001b[49m\u001b[43m_commit_hash\u001b[49m\u001b[38;5;241;43m=\u001b[39;49m\u001b[43mcommit_hash\u001b[49m\u001b[43m,\u001b[49m\n\u001b[1;32m    702\u001b[0m \u001b[43m    \u001b[49m\u001b[43m)\u001b[49m\n\u001b[1;32m    703\u001b[0m     commit_hash \u001b[38;5;241m=\u001b[39m extract_commit_hash(resolved_config_file, commit_hash)\n\u001b[1;32m    704\u001b[0m \u001b[38;5;28;01mexcept\u001b[39;00m \u001b[38;5;167;01mEnvironmentError\u001b[39;00m:\n\u001b[1;32m    705\u001b[0m     \u001b[38;5;66;03m# Raise any environment error raise by `cached_file`. It will have a helpful error message adapted to\u001b[39;00m\n\u001b[1;32m    706\u001b[0m     \u001b[38;5;66;03m# the original exception.\u001b[39;00m\n",
      "File \u001b[0;32m~/.pyenv/versions/3.10.6/envs/JC/lib/python3.10/site-packages/transformers/utils/hub.py:425\u001b[0m, in \u001b[0;36mcached_file\u001b[0;34m(path_or_repo_id, filename, cache_dir, force_download, resume_download, proxies, token, revision, local_files_only, subfolder, repo_type, user_agent, _raise_exceptions_for_missing_entries, _raise_exceptions_for_connection_errors, _commit_hash, **deprecated_kwargs)\u001b[0m\n\u001b[1;32m    423\u001b[0m     \u001b[38;5;28;01mif\u001b[39;00m \u001b[38;5;129;01mnot\u001b[39;00m _raise_exceptions_for_missing_entries \u001b[38;5;129;01mor\u001b[39;00m \u001b[38;5;129;01mnot\u001b[39;00m _raise_exceptions_for_connection_errors:\n\u001b[1;32m    424\u001b[0m         \u001b[38;5;28;01mreturn\u001b[39;00m \u001b[38;5;28;01mNone\u001b[39;00m\n\u001b[0;32m--> 425\u001b[0m     \u001b[38;5;28;01mraise\u001b[39;00m \u001b[38;5;167;01mEnvironmentError\u001b[39;00m(\n\u001b[1;32m    426\u001b[0m         \u001b[38;5;124mf\u001b[39m\u001b[38;5;124m\"\u001b[39m\u001b[38;5;124mWe couldn\u001b[39m\u001b[38;5;124m'\u001b[39m\u001b[38;5;124mt connect to \u001b[39m\u001b[38;5;124m'\u001b[39m\u001b[38;5;132;01m{\u001b[39;00mHUGGINGFACE_CO_RESOLVE_ENDPOINT\u001b[38;5;132;01m}\u001b[39;00m\u001b[38;5;124m'\u001b[39m\u001b[38;5;124m to load this file, couldn\u001b[39m\u001b[38;5;124m'\u001b[39m\u001b[38;5;124mt find it in the\u001b[39m\u001b[38;5;124m\"\u001b[39m\n\u001b[1;32m    427\u001b[0m         \u001b[38;5;124mf\u001b[39m\u001b[38;5;124m\"\u001b[39m\u001b[38;5;124m cached files and it looks like \u001b[39m\u001b[38;5;132;01m{\u001b[39;00mpath_or_repo_id\u001b[38;5;132;01m}\u001b[39;00m\u001b[38;5;124m is not the path to a directory containing a file named\u001b[39m\u001b[38;5;124m\"\u001b[39m\n\u001b[1;32m    428\u001b[0m         \u001b[38;5;124mf\u001b[39m\u001b[38;5;124m\"\u001b[39m\u001b[38;5;124m \u001b[39m\u001b[38;5;132;01m{\u001b[39;00mfull_filename\u001b[38;5;132;01m}\u001b[39;00m\u001b[38;5;124m.\u001b[39m\u001b[38;5;130;01m\\n\u001b[39;00m\u001b[38;5;124mCheckout your internet connection or see how to run the library in offline mode at\u001b[39m\u001b[38;5;124m\"\u001b[39m\n\u001b[1;32m    429\u001b[0m         \u001b[38;5;124m\"\u001b[39m\u001b[38;5;124m \u001b[39m\u001b[38;5;124m'\u001b[39m\u001b[38;5;124mhttps://huggingface.co/docs/transformers/installation#offline-mode\u001b[39m\u001b[38;5;124m'\u001b[39m\u001b[38;5;124m.\u001b[39m\u001b[38;5;124m\"\u001b[39m\n\u001b[1;32m    430\u001b[0m     ) \u001b[38;5;28;01mfrom\u001b[39;00m \u001b[38;5;21;01me\u001b[39;00m\n\u001b[1;32m    431\u001b[0m \u001b[38;5;28;01mexcept\u001b[39;00m EntryNotFoundError \u001b[38;5;28;01mas\u001b[39;00m e:\n\u001b[1;32m    432\u001b[0m     \u001b[38;5;28;01mif\u001b[39;00m \u001b[38;5;129;01mnot\u001b[39;00m _raise_exceptions_for_missing_entries:\n",
      "\u001b[0;31mOSError\u001b[0m: We couldn't connect to 'https://huggingface.co' to load this file, couldn't find it in the cached files and it looks like Cybernetyx/TARS_v0.2_QZ_ZS_1K is not the path to a directory containing a file named config.json.\nCheckout your internet connection or see how to run the library in offline mode at 'https://huggingface.co/docs/transformers/installation#offline-mode'."
     ]
    }
   ],
   "source": [
    "model = pipeline(\"text-generation\", model=\"Cybernetyx/TARS_v0.2_QZ_ZS_1K\")"
   ]
  },
  {
   "cell_type": "code",
   "execution_count": null,
   "id": "08a12924",
   "metadata": {},
   "outputs": [],
   "source": []
  },
  {
   "cell_type": "code",
   "execution_count": null,
   "id": "4819a279",
   "metadata": {},
   "outputs": [],
   "source": []
  },
  {
   "cell_type": "code",
   "execution_count": 34,
   "id": "a929231d",
   "metadata": {},
   "outputs": [
    {
     "ename": "ImportError",
     "evalue": "cannot import name 'undefined' from 'transformers' (/home/jessica/.pyenv/versions/3.10.6/envs/JC/lib/python3.10/site-packages/transformers/__init__.py)",
     "output_type": "error",
     "traceback": [
      "\u001b[0;31m---------------------------------------------------------------------------\u001b[0m",
      "\u001b[0;31mImportError\u001b[0m                               Traceback (most recent call last)",
      "Cell \u001b[0;32mIn [34], line 1\u001b[0m\n\u001b[0;32m----> 1\u001b[0m \u001b[38;5;28;01mfrom\u001b[39;00m \u001b[38;5;21;01mtransformers\u001b[39;00m \u001b[38;5;28;01mimport\u001b[39;00m undefined\n\u001b[1;32m      3\u001b[0m model \u001b[38;5;241m=\u001b[39m undefined\u001b[38;5;241m.\u001b[39mfrom_pretrained(\u001b[38;5;124m\"\u001b[39m\u001b[38;5;124mundefined\u001b[39m\u001b[38;5;124m\"\u001b[39m)\n\u001b[1;32m      4\u001b[0m model\u001b[38;5;241m.\u001b[39mload_adapter(\u001b[38;5;124m\"\u001b[39m\u001b[38;5;124mCybernetyx/TARS_v0.2_QZ_ZS_1K\u001b[39m\u001b[38;5;124m\"\u001b[39m, source\u001b[38;5;241m=\u001b[39m\u001b[38;5;124m\"\u001b[39m\u001b[38;5;124mhf\u001b[39m\u001b[38;5;124m\"\u001b[39m)\n",
      "\u001b[0;31mImportError\u001b[0m: cannot import name 'undefined' from 'transformers' (/home/jessica/.pyenv/versions/3.10.6/envs/JC/lib/python3.10/site-packages/transformers/__init__.py)"
     ]
    }
   ],
   "source": [
    "from transformers import undefined\n",
    "\n",
    "model = undefined.from_pretrained(\"undefined\")\n",
    "model.load_adapter(\"Cybernetyx/TARS_v0.2_QZ_ZS_1K\", source=\"hf\")"
   ]
  },
  {
   "cell_type": "code",
   "execution_count": null,
   "id": "a7d3427d",
   "metadata": {},
   "outputs": [],
   "source": [
    "prompt = \"In which year was the French Revolution?\"\n",
    "generated_questions = model(prompt, num_return_sequences=5)\n",
    "for question in generated_questions:\n",
    "    print(question['generated_text'])"
   ]
  }
 ],
 "metadata": {
  "kernelspec": {
   "display_name": "Python 3 (ipykernel)",
   "language": "python",
   "name": "python3"
  },
  "language_info": {
   "codemirror_mode": {
    "name": "ipython",
    "version": 3
   },
   "file_extension": ".py",
   "mimetype": "text/x-python",
   "name": "python",
   "nbconvert_exporter": "python",
   "pygments_lexer": "ipython3",
   "version": "3.10.6"
  },
  "toc": {
   "base_numbering": 1,
   "nav_menu": {},
   "number_sections": true,
   "sideBar": true,
   "skip_h1_title": false,
   "title_cell": "Table of Contents",
   "title_sidebar": "Contents",
   "toc_cell": false,
   "toc_position": {},
   "toc_section_display": true,
   "toc_window_display": false
  }
 },
 "nbformat": 4,
 "nbformat_minor": 5
}
